D:\Anaconda3\python.exe "D:\Program Files\PyCharm 2018.1.4\helpers\pydev\pydevd.py" --multiproc --client 127.0.0.1 --port 52129 --file D:/PycharmProjects/pTransE-master/wiki_data/wiki_read.py
pydev debugger: process 5644 is connecting
Connected to pydev debugger (build 181.5087.37)

Traceback (most recent call last):
  File "<string>", line 1, in <module>
  File "D:\Anaconda3\lib\multiprocessing\spawn.py", line 105, in spawn_main
    exitcode = _main(fd)
  File "D:\Anaconda3\lib\multiprocessing\spawn.py", line 114, in _main
    prepare(preparation_data)
  File "D:\Anaconda3\lib\multiprocessing\spawn.py", line 225, in prepare
    _fixup_main_from_path(data['init_main_from_path'])
  File "D:\Anaconda3\lib\multiprocessing\spawn.py", line 277, in _fixup_main_from_path
    run_name="__mp_main__")
  File "D:\Anaconda3\lib\runpy.py", line 263, in run_path
    pkg_name=pkg_name, script_name=fname)
  File "D:\Anaconda3\lib\runpy.py", line 96, in _run_module_code
    mod_name, mod_spec, pkg_name, script_name)
  File "D:\Anaconda3\lib\runpy.py", line 85, in _run_code
    exec(code, run_globals)
  File "D:\PycharmProjects\pTransE-master\wiki_data\wiki_read.py", line 10, in <module>
    wiki = WikiCorpus(inp, lemmatize=False)
  File "D:\Anaconda3\lib\site-packages\gensim\corpora\wikicorpus.py", line 289, in __init__
    self.dictionary = Dictionary(self.get_texts())
  File "D:\Anaconda3\lib\site-packages\gensim\corpora\dictionary.py", line 58, in __init__
    self.add_documents(documents, prune_at=prune_at)
  File "D:\Anaconda3\lib\site-packages\gensim\corpora\dictionary.py", line 111, in add_documents
    for docno, document in enumerate(documents):
  File "D:\Anaconda3\lib\site-packages\gensim\corpora\wikicorpus.py", line 313, in get_texts
    pool = multiprocessing.Pool(self.processes, init_to_ignore_interrupt)
  File "D:\Anaconda3\lib\multiprocessing\context.py", line 119, in Pool
    context=self.get_context())
  File "D:\Anaconda3\lib\multiprocessing\pool.py", line 174, in __init__
    self._repopulate_pool()
  File "D:\Anaconda3\lib\multiprocessing\pool.py", line 239, in _repopulate_pool
    w.start()
  File "D:\Anaconda3\lib\multiprocessing\process.py", line 105, in start
    self._popen = self._Popen(self)
  File "D:\Anaconda3\lib\multiprocessing\context.py", line 322, in _Popen
    return Popen(process_obj)
  File "D:\Anaconda3\lib\multiprocessing\popen_spawn_win32.py", line 33, in __init__
    prep_data = spawn.get_preparation_data(process_obj._name)
  File "D:\Anaconda3\lib\multiprocessing\spawn.py", line 143, in get_preparation_data
    _check_not_importing_main()
  File "D:\Anaconda3\lib\multiprocessing\spawn.py", line 136, in _check_not_importing_main
    is not going to be frozen to produce an executable.''')
RuntimeError: 
        An attempt has been made to start a new process before the
        current process has finished its bootstrapping phase.

        This probably means that you are not using fork to start your
        child processes and you have forgotten to use the proper idiom
        in the main module:

            if __name__ == '__main__':
                freeze_support()
                ...

        The "freeze_support()" line can be omitted if the program
        is not going to be frozen to produce an executable.

Process finished with exit code -1
